Workbook

Sheet Posta Americana
A1: Juegos del Orgullo 2025
A2: Natación - AAAJ
A4: Planilla de Inscripción
A5: Posta americana 6x100x40
A7: Club
A8: Equipo
A9: Categoría
A10: Entrenador
A12: Nadador | B12: Nombre y Apellido | C12: DNI | D12: Fecha nacimiento | E12: Edad
A13: 1 | E13: =DATEDIF(D13,TODAY(),"Y") -> 126
A14: 2 | E14: =DATEDIF(D14,TODAY(),"Y") -> 126
A15: 3 | E15: =DATEDIF(D15,TODAY(),"Y") -> 126
A16: 4 | E16: =DATEDIF(D16,TODAY(),"Y") -> 126
A17: 5 | E17: =DATEDIF(D17,TODAY(),"Y") -> 126
A18: 6 | E18: =DATEDIF(D18,TODAY(),"Y") -> 126
A20: Se pueden preinscribir la cantidad de Postas que deseen por equipo o institución, pero sólo las primeras dos quedarán automáticamente inscriptas,
A21: las demás se definirán dependiendo la cantidad de equipos inscriptos una vez concluida la etapa de preinscripciones
A24: Club
A25: Equipo
A26: Categoría
A27: Entrenador
A29: Nadador | B29: Nombre y Apellido | C29: DNI | D29: Fecha nacimiento | E29: Edad
A30: 1 | E30: =DATEDIF(D30,TODAY(),"Y") -> 126
A31: 2 | E31: =DATEDIF(D31,TODAY(),"Y") -> 126
A32: 3 | E32: =DATEDIF(D32,TODAY(),"Y") -> 126
A33: 4 | E33: =DATEDIF(D33,TODAY(),"Y") -> 126
A34: 5 | E34: =DATEDIF(D34,TODAY(),"Y") -> 126
A35: 6 | E35: =DATEDIF(D35,TODAY(),"Y") -> 126
A37: Se pueden preinscribir la cantidad de Postas que deseen por equipo o institución, pero sólo las primeras dos quedarán automáticamente inscriptas,
A38: las demás se definirán dependiendo la cantidad de equipos inscriptos una vez concluida la etapa de preinscripciones

Sheet Pruebas individuales
A1: Juegos del Orgullo 2026
A2: Natación - AAAJ
A4: Planilla de Inscripción
A5: Pruebas individuales
A7: Equipo | B7: Prueba | C7: Nombre y Apellido | D7: DNI | E7: Fecha nacimiento | F7: Edad | G7: Categoría | H7: Género | I7: Minutos | J7: Segundos | K7: Centésimas | L7: Tiempo sembrado
A8: PIRAÑAS | B8: 2 - 50 Libres | C8: Gonzalo Larran | D8: 31404363 | E8: 31141 | F8: =DATEDIF(E8,DATE(2026,12,31),"Y") -> 41 | G8: =+VLOOKUP(F8,Validación!C:D,2,FALSE) -> E | H8: M | I8: 0 | J8: 36 | K8: 0 | L8: =TEXT(I8,"00")&":"&TEXT(J8,"00")&","&TEXT(K8,"00") -> 00:36,00
A9: PIRAÑAS | B9: 2 - 50 Libres | C9: Claudio Avalos | D9: 28829308 | E9: 29755 | F9: 45 | G9: F | H9: M | I9: 0 | J9: 35 | K9: 0 | L9: =TEXT(I9,"00")&":"&TEXT(J9,"00")&","&TEXT(K9,"00") -> 00:35,00
A10: PIRAÑAS | B10: 2 - 50 Libres | C10: Gabriel Da Vita | D10: 19132515 | E10: 34939 | F10: =DATEDIF(E10,DATE(2026,12,31),"Y") -> 31 | G10: =+VLOOKUP(F10,Validación!C:D,2,FALSE) -> C | H10: M | I10: 0 | J10: 31 | K10: 0 | L10: 00:31;00
A11: PIRAÑAS | B11: 2 - 50 Libres | C11: Muriel Bravo | D11: 96291154 | E11: 38385 | F11: =DATEDIF(E11,DATE(2026,12,31),"Y") -> 21 | G11: A | H11: M | I11: 0 | J11: 38 | K11: 0 | L11: =TEXT(I11,"00")&":"&TEXT(J11,"00")&","&TEXT(K11,"00") -> 00:38,00
A12: PIRAÑAS | B12: 2 - 50 Libres | C12: Sebastian Arias | D12: 37767077 | E12: 34279 | F12: =DATEDIF(E12,DATE(2026,12,31),"Y") -> 33 | G12: =+VLOOKUP(F12,Validación!C:D,2,FALSE) -> C | H12: M | I12: 0 | J12: 37 | K12: 40 | L12: =TEXT(I12,"00")&":"&TEXT(J12,"00")&","&TEXT(K12,"00") -> 00:37,40
A13: PIRAÑAS | B13: 2 - 50 Libres | C13: Lautaro Yapur | D13: 38132162 | E13: 34433 | F13: =DATEDIF(E13,DATE(2026,12,31),"Y") -> 32 | G13: =+VLOOKUP(F13,Validación!C:D,2,FALSE) -> C | H13: M | I13: 0 | J13: 42 | K13: 0 | L13: =TEXT(I13,"00")&":"&TEXT(J13,"00")&","&TEXT(K13,"00") -> 00:42,00
A14: PIRAÑAS | B14: 2 - 50 Libres | C14: Pedro Gomes Bezerra | D14: 95686614 | E14: 34891 | F14: 31 | G14: C | H14: M | I14: 0 | J14: 33 | K14: 11 | L14: =TEXT(I14,"00")&":"&TEXT(J14,"00")&","&TEXT(K14,"00") -> 00:33,11
A15: PIRAÑAS | B15: 2 - 50 Libres | C15: Valentin Bussolini | D15: 44917765 | E15: 37795 | F15: =DATEDIF(E15,DATE(2026,12,31),"Y") -> 23 | G15: =+VLOOKUP(F15,Validación!C:D,2,FALSE) -> A | H15: M | I15: 0 | J15: 37 | K15: 0 | L15: =TEXT(I15,"00")&":"&TEXT(J15,"00")&","&TEXT(K15,"00") -> 00:37,00
A16: PIRAÑAS | B16: 2 - 50 Libres | C16: Martin Signifredi | D16: 34934235 | E16: 32919 | F16: =DATEDIF(E16,DATE(2026,12,31),"Y") -> 36 | G16: =+VLOOKUP(F16,Validación!C:D,2,FALSE) -> D | H16: M | I16: 0 | J16: 33 | K16: 0 | L16: =TEXT(I16,"00")&":"&TEXT(J16,"00")&","&TEXT(K16,"00") -> 00:33,00
A17: PIRAÑAS | B17: 2 - 50 Libres | C17: Pablo Villegas | D17: 40362905 | E17: 32930 | F17: =DATEDIF(E17,DATE(2026,12,31),"Y") -> 36 | G17: =+VLOOKUP(F17,Validación!C:D,2,FALSE) -> D | H17: M | I17: 0 | J17: 32 | K17: 6 | L17: =TEXT(I17,"00")&":"&TEXT(J17,"00")&","&TEXT(K17,"00") -> 00:32,06
A18: PIRAÑAS | B18: 2 - 50 Libres | C18: Jonatan Morabes | D18: 30861672 | E18: 30701 | F18: =DATEDIF(E18,DATE(2026,12,31),"Y") -> 42 | G18: =+VLOOKUP(F18,Validación!C:D,2,FALSE) -> E | H18: M | I18: 0 | J18: 38 | K18: 3 | L18: =TEXT(I18,"00")&":"&TEXT(J18,"00")&","&TEXT(K18,"00") -> 00:38,03
A19: PIRAÑAS | B19: 2 - 50 Libres | C19: Pablo Facciuto | D19: 32251124 | E19: 31849 | F19: =DATEDIF(E19,DATE(2026,12,31),"Y") -> 39 | G19: =+VLOOKUP(F19,Validación!C:D,2,FALSE) -> D | H19: M | I19: 0 | J19: 32 | K19: 8 | L19: =TEXT(I19,"00")&":"&TEXT(J19,"00")&","&TEXT(K19,"00") -> 00:32,08
A20: PIRAÑAS | B20: 2 - 50 Libres | C20: Victor Juarez | D20: 36005142 | E20: 33635 | F20: =DATEDIF(E20,DATE(2026,12,31),"Y") -> 34 | G20: =+VLOOKUP(F20,Validación!C:D,2,FALSE) -> C | H20: M | I20: 0 | J20: 36 | K20: 3 | L20: =TEXT(I20,"00")&":"&TEXT(J20,"00")&","&TEXT(K20,"00") -> 00:36,03
A21: PIRAÑAS | B21: 2 - 50 Libres | C21: Adelquis D´amante | D21: 34937080 | E21: 32848 | F21: =DATEDIF(E21,DATE(2026,12,31),"Y") -> 37 | G21: =+VLOOKUP(F21,Validación!C:D,2,FALSE) -> D | H21: M | I21: 0 | J21: 32 | K21: 8 | L21: =TEXT(I21,"00")&":"&TEXT(J21,"00")&","&TEXT(K21,"00") -> 00:32,08
A22: PIRAÑAS | B22: 2 - 50 Libres | C22: Roman Blanco | D22: 40969916 | E22: 35872 | F22: =DATEDIF(E22,DATE(2026,12,31),"Y") -> 28 | G22: =+VLOOKUP(F22,Validación!C:D,2,FALSE) -> B | H22: M | I22: 0 | J22: 49 | K22: 7 | L22: =TEXT(I22,"00")&":"&TEXT(J22,"00")&","&TEXT(K22,"00") -> 00:49,07
A23: PIRAÑAS | B23: 2 - 50 Libres | C23: Martin Morel | D23: 30476072 | E23: 30676 | F23: =DATEDIF(E23,DATE(2026,12,31),"Y") -> 43 | G23: E | H23: M | I23: 0 | J23: 43 | K23: 0 | L23: =TEXT(I23,"00")&":"&TEXT(J23,"00")&","&TEXT(K23,"00") -> 00:43,00
A24: PIRAÑAS | B24: 2 - 50 Libres | C24: Facundo Martinez | D24: 36238855 | E24: 33457 | F24: =DATEDIF(E24,DATE(2026,12,31),"Y") -> 35 | G24: =+VLOOKUP(F24,Validación!C:D,2,FALSE) -> D | H24: M | I24: 0 | J24: 34 | K24: 4 | L24: =TEXT(I24,"00")&":"&TEXT(J24,"00")&","&TEXT(K24,"00") -> 00:34,04
A25: PIRAÑAS | B25: 3 - 50 Pecho | C25: Martin Morel | D25: 30476072 | E25: 30676 | F25: 43 | G25: E | H25: M | I25: 0 | J25: 58 | K25: 0 | L25: =TEXT(I25,"00")&":"&TEXT(J25,"00")&","&TEXT(K25,"00") -> 00:58,00
A26: PIRAÑAS | B26: 3 - 50 Pecho | C26: Claudio Avalos | D26: 28829308 | E26: 29755 | F26: 45 | G26: F | H26: M | I26: 0 | J26: 46 | K26: 5 | L26: =TEXT(I26,"00")&":"&TEXT(J26,"00")&","&TEXT(K26,"00") -> 00:46,05
A27: PIRAÑAS | B27: 3 - 50 Pecho | C27: Gonzalo Larran | D27: 31404363 | E27: 31141 | F27: =DATEDIF(E27,DATE(2026,12,31),"Y") -> 41 | G27: =+VLOOKUP(F27,Validación!C:D,2,FALSE) -> E | H27: M | I27: 0 | J27: 44 | K27: 5 | L27: =TEXT(I27,"00")&":"&TEXT(J27,"00")&","&TEXT(K27,"00") -> 00:44,05
A28: PIRAÑAS | B28: 3 - 50 Pecho | C28: Leandro Carletti | D28: 34118815 | E28: 32541 | F28: =DATEDIF(E28,DATE(2026,12,31),"Y") -> 37 | G28: D | H28: M | I28: 0 | J28: 35 | K28: 0 | L28: =TEXT(I28,"00")&":"&TEXT(J28,"00")&","&TEXT(K28,"00") -> 00:35,00
A29: PIRAÑAS | B29: 3 - 50 Pecho | C29: Pedro Gomes Bezerra | D29: 95686614 | E29: 34891 | F29: 31 | G29: C | H29: M | I29: 0 | J29: 38 | K29: 1 | L29: =TEXT(I29,"00")&":"&TEXT(J29,"00")&","&TEXT(K29,"00") -> 00:38,01
A30: PIRAÑAS | B30: 3 - 50 Pecho | C30: Valentin Bussolini | D30: 44917765 | E30: 37795 | F30: =DATEDIF(E30,DATE(2026,12,31),"Y") -> 23 | G30: =+VLOOKUP(F30,Validación!C:D,2,FALSE) -> A | H30: M | I30: 0 | J30: 47 | K30: 0 | L30: =TEXT(I30,"00")&":"&TEXT(J30,"00")&","&TEXT(K30,"00") -> 00:47,00
A31: PIRAÑAS | B31: 3 - 50 Pecho | C31: Lucas Alfonso | D31: 43909982 | E31: 37323 | F31: =DATEDIF(E31,DATE(2026,12,31),"Y") -> 24 | G31: =+VLOOKUP(F31,Validación!C:D,2,FALSE) -> A | H31: M | I31: 0 | J31: 43 | K31: 70 | L31: =TEXT(I31,"00")&":"&TEXT(J31,"00")&","&TEXT(K31,"00") -> 00:43,70
A32: PIRAÑAS | B32: 3 - 50 Pecho | C32: Jonatan Morabes | D32: 30861672 | E32: 30701 | F32: =DATEDIF(E32,DATE(2026,12,31),"Y") -> 42 | G32: =+VLOOKUP(F32,Validación!C:D,2,FALSE) -> E | H32: M | I32: 0 | J32: 50 | K32: 50 | L32: =TEXT(I32,"00")&":"&TEXT(J32,"00")&","&TEXT(K32,"00") -> 00:50,50
A33: PIRAÑAS | B33: 3 - 50 Pecho | C33: Victor Juarez | D33: 36005142 | E33: 33635 | F33: =DATEDIF(E33,DATE(2026,12,31),"Y") -> 34 | G33: =+VLOOKUP(F33,Validación!C:D,2,FALSE) -> C | H33: M | I33: 0 | J33: 50 | K33: 0 | L33: =TEXT(I33,"00")&":"&TEXT(J33,"00")&","&TEXT(K33,"00") -> 00:50,00
A34: PIRAÑAS | B34: 3 - 50 Pecho | C34: Adelquis D´amante | D34: 34937080 | E34: 32848 | F34: =DATEDIF(E34,DATE(2026,12,31),"Y") -> 37 | G34: =+VLOOKUP(F34,Validación!C:D,2,FALSE) -> D | H34: M | I34: 0 | J34: 45 | K34: 0 | L34: =TEXT(I34,"00")&":"&TEXT(J34,"00")&","&TEXT(K34,"00") -> 00:45,00
A35: PIRAÑAS | B35: 3 - 50 Pecho | C35: Facundo Martinez | D35: 36238855 | E35: 33457 | F35: =DATEDIF(E35,DATE(2026,12,31),"Y") -> 35 | G35: =+VLOOKUP(F35,Validación!C:D,2,FALSE) -> D | H35: M | I35: 0 | J35: 45 | K35: 20 | L35: =TEXT(I35,"00")&":"&TEXT(J35,"00")&","&TEXT(K35,"00") -> 00:45,20
A36: PIRAÑAS | B36: 3 - 50 Pecho | C36: Nahuel Sosa | D36: 37579659 | E36: 34234 | F36: =DATEDIF(E36,DATE(2026,12,31),"Y") -> 33 | G36: =+VLOOKUP(F36,Validación!C:D,2,FALSE) -> C | H36: M | I36: 0 | J36: 50 | K36: 0 | L36: =TEXT(I36,"00")&":"&TEXT(J36,"00")&","&TEXT(K36,"00") -> 00:50,00
A37: PIRAÑAS | B37: 3 - 50 Pecho | C37: Gaston Martinez | D37: 29664205 | E37: 30175 | F37: =DATEDIF(E37,DATE(2026,12,31),"Y") -> 44 | G37: =+VLOOKUP(F37,Validación!C:D,2,FALSE) -> E | H37: M | I37: 0 | J37: 45 | K37: 0 | L37: =TEXT(I37,"00")&":"&TEXT(J37,"00")&","&TEXT(K37,"00") -> 00:45,00
A38: PIRAÑAS | B38: 3 - 50 Pecho | C38: Martin Giavarini | D38: 36658642 | E38: 33945 | F38: =DATEDIF(E38,DATE(2026,12,31),"Y") -> 34 | G38: =+VLOOKUP(F38,Validación!C:D,2,FALSE) -> C | H38: M | I38: 0 | J38: 42 | K38: 20 | L38: =TEXT(I38,"00")&":"&TEXT(J38,"00")&","&TEXT(K38,"00") -> 00:42,20
A39: PIRAÑAS | B39: 6- 50 Espalda | C39: Lautaro Yapur | D39: 38132162 | E39: 34433 | F39: =DATEDIF(E39,DATE(2026,12,31),"Y") -> 32 | G39: =+VLOOKUP(F39,Validación!C:D,2,FALSE) -> C | H39: M | I39: 0 | J39: 57 | K39: 60 | L39: =TEXT(I39,"00")&":"&TEXT(J39,"00")&","&TEXT(K39,"00") -> 00:57,60
A40: PIRAÑAS | B40: 6- 50 Espalda | C40: Martin Signifredi | D40: 34934235 | E40: 32919 | F40: =DATEDIF(E40,DATE(2026,12,31),"Y") -> 36 | G40: =+VLOOKUP(F40,Validación!C:D,2,FALSE) -> D | H40: M | I40: 0 | J40: 42 | K40: 10 | L40: =TEXT(I40,"00")&":"&TEXT(J40,"00")&","&TEXT(K40,"00") -> 00:42,10
A41: PIRAÑAS | B41: 6- 50 Espalda | C41: Muriel Bravo | D41: 96291154 | E41: 38385 | F41: =DATEDIF(E41,DATE(2026,12,31),"Y") -> 21 | G41: A | H41: M | I41: 0 | J41: 44 | K41: 40 | L41: =TEXT(I41,"00")&":"&TEXT(J41,"00")&","&TEXT(K41,"00") -> 00:44,40
A42: PIRAÑAS | B42: 6- 50 Espalda | C42: Martin Morel | D42: 30476072 | E42: 30676 | F42: 43 | G42: E | H42: M | I42: 0 | J42: 49 | K42: 0 | L42: =TEXT(I42,"00")&":"&TEXT(J42,"00")&","&TEXT(K42,"00") -> 00:49,00
...

Sheet Validación
A1: Prueba | C1: Edad | D1: Categoría | F1: Género
A2: 1 - 400 Libres | C2: 18 | D2: A | F2: F
A3: 2 - 50 Libres | C3: 19 | D3: A | F3: M
A4: 3 - 50 Pecho | C4: 20 | D4: A | F4: Open
A5: 4 - 50 Libres - Bautismo | C5: 21 | D5: A
A6: 5 - 200 Medley | C6: 22 | D6: A
A7: 6- 50 Espalda | C7: 23 | D7: A
A8: 7 - 50 Pecho - Bautismo | C8: 24 | D8: A
A9: 8 - 100 Libres | C9: 25 | D9: B
A10: 9 - 50 Mariposa | C10: 26 | D10: B
A11: 10 - 50 Espalda - Bautismo | C11: 27 | D11: B
C12: 28 | D12: B
C13: 29 | D13: B
C14: 30 | D14: C
C15: 31 | D15: C
C16: 32 | D16: C
C17: 33 | D17: C
C18: 34 | D18: C
C19: 35 | D19: D
C20: 36 | D20: D
C21: 37 | D21: D
C22: 38 | D22: D
C23: 39 | D23: D
... C73: 89 | D73: J

Sheet Postas por equipos
A1: Juegos del Orgullo 2026
A2: Natación - AAAJ
A5: Planilla de Inscripción
A6: Posta 4x50 Medley
A8: Equipo | B8: Prueba | C8: Nombre y Apellido | D8: DNI | E8: Fecha nacimiento | F8: Edad | G8: Categoria
A9: A | B9: 11- 4x50 Medley | C9: Leonel Contreras | D9: 45269460 | E9: 37863 | F9: =DATEDIF(E9,DATE(2026,12,31),"Y") -> 23 | G9: B
C10: Pedro Gomes Bezerra | D10: 95686614 | E10: 34891 | F10: =DATEDIF(E10,DATE(2026,12,31),"Y") -> 31
C11: Francisco Ribeiro Camargo | D11: 96233792 | E11: 33248 | F11: =DATEDIF(E11,DATE(2026,12,31),"Y") -> 35
C12: Leandro Carletti | D12: 34118815 | E12: 32541 | F12: 37
A13: B | B13: 11- 4x50 Medley | C13: Muriel Bravo | D13: 96291154 | E13: 38385 | F13: =DATEDIF(E13,DATE(2026,12,31),"Y") -> 21 | G13: A
C14: Lautaro Yapur | D14: 38132162 | E14: 34433 | F14: =DATEDIF(E14,DATE(2026,12,31),"Y") -> 32
C15: Valentin Bussolini | D15: 44917765 | E15: 37795 | F15: =DATEDIF(E15,DATE(2026,12,31),"Y") -> 23
C16: Lucas Alfonso | D16: 43909982 | E16: 37323 | F16: =DATEDIF(E16,DATE(2026,12,31),"Y") -> 24
A17: C | B17: 11- 4x50 Medley | C17: Gaston Martinez | D17: 29664205 | E17: 30175 | F17: =DATEDIF(E17,DATE(2026,12,31),"Y") -> 44 | G17: C
C18: Jonatan Morabes | D18: 30861672 | E18: 30701 | F18: =DATEDIF(E18,DATE(2026,12,31),"Y") -> 42
C19: Gonzalo Larran | D19: 31404363 | E19: 31141 | F19: =DATEDIF(E19,DATE(2026,12,31),"Y") -> 41
C20: Claudio Avalos | D20: 28829308 | E20: 29755 | F20: 45
A21: D | B21: 11- 4x50 Medley | C21: Adelquis D´amante | D21: 34937080 | E21: 32848 | F21: =DATEDIF(E21,DATE(2026,12,31),"Y") -> 37 | G21: C
C22: Martin Signifredi | D22: 34934235 | E22: 32919 | F22: =DATEDIF(E22,DATE(2026,12,31),"Y") -> 36
C23: Martin Giavarini | D23: 36658642 | E23: 33945 | F23: =DATEDIF(E23,DATE(2026,12,31),"Y") -> 34
C24: Pablo Villegas | D24: 40362905 | E24: 32930 | F24: =DATEDIF(E24,DATE(2026,12,31),"Y") -> 36
A25: E | B25: 11- 4x50 Medley | C25: Facundo Martinez | D25: 36238855 | E25: 33457 | F25: =DATEDIF(E25,DATE(2026,12,31),"Y") -> 35 | G25: B
C26: Nahuel Sosa | D26: 37579659 | E26: 34234 | F26: =DATEDIF(E26,DATE(2026,12,31),"Y") -> 33
C27: Pablo Facciuto | D27: 32251124 | E27: 31849 | F27: =DATEDIF(E27,DATE(2026,12,31),"Y") -> 39
C28: Gabriel Da Vita | D28: 19132515 | E28: 34939 | F28: =DATEDIF(E28,DATE(2026,12,31),"Y") -> 31
A29: F | B29: 11- 4x50 Medley | C29: Sebastian Arias | D29: 37767077 | E29: 34279 | F29: =DATEDIF(E29,DATE(2026,12,31),"Y") -> 33 | G29: B
C30: Roman Blanco | D30: 40969916 | E30: 35872 | F30: =DATEDIF(E30,DATE(2026,12,31),"Y") -> 28
C31: Victor Juarez | D31: 36005142 | E31: 33635 | F31: =DATEDIF(E31,DATE(2026,12,31),"Y") -> 34
C32: Martin Morel | D32: 30476072 | E32: 30676 | F32: =DATEDIF(E32,DATE(2026,12,31),"Y") -> 43
B33: 11- 4x50 Medley | F33: =DATEDIF(E33,DATE(2026,12,31),"Y") -> 126
F34: =DATEDIF(E34,DATE(2026,12,31),"Y") -> 126
F35: =DATEDIF(E35,DATE(2026,12,31),"Y") -> 126
F36: =DATEDIF(E36,DATE(2026,12,31),"Y") -> 126
A40: Planilla de Inscripción
A41: Posta 4x50 Libres
A43: Equipo | B43: Prueba | C43: Nombre y Apellido | D43: DNI | E43: Fecha nacimiento | F43: Edad | G43: Categoria
A44: A | B44: 12- 4x50 Libres | C44: Leonel Contreras | D44: 45269460 | E44: 37863 | F44: =DATEDIF(E44,DATE(2026,12,31),"Y") -> 23 | G44: B
C45: Pedro Gomes Bezerra | D45: 95686614 | E45: 34891 | F45: =DATEDIF(E45,DATE(2026,12,31),"Y") -> 31
C46: Francisco Ribeiro Camargo | D46: 96233792 | E46: 33248 | F46: =DATEDIF(E46,DATE(2026,12,31),"Y") -> 35
C47: Leandro Carletti | D47: 34118815 | E47: 32541 | F47: =DATEDIF(E47,DATE(2026,12,31),"Y") -> 37
...
